<?xml version="1.0" encoding="utf-8"?>
<!-- =================================================================================== -->
<!-- |    This document was autogenerated by xacro from /home/yuto/catkin_ws/src/multi_legged_robot/multi_legged_description/robots/multi_legged_robot.urdf.xacro | -->
<!-- |    EDITING THIS FILE BY HAND IS NOT RECOMMENDED                                 | -->
<!-- =================================================================================== -->
<robot name="multi_legged_robot">
  <!--link name="world"/>
  <joint name="fixed" type="fixed">
    <parent link="world"/>
    <child link="base_footprint"/>
  </joint-->
  <!-- ===============  Link & Joint =============== -->
  <!-- Base -->
  <link name="base_footprint"/>
  <joint name="base_link_joint" type="fixed">
    <origin xyz="0 0 1.0"/>
    <parent link="base_footprint"/>
    <child link="base_link"/>
  </joint>
  <link name="base_link">
    <visual>
      <geometry>
        <box size="0.5 0.3 0.15"/>
      </geometry>
    </visual>
    <collision>
      <geometry>
        <box size="0.5 0.3 0.15"/>
      </geometry>
    </collision>
    <inertial>
      <mass value="5.0"/>
      <inertia ixx="0.046875" ixy="0.0" ixz="0.0" iyy="0.113541666667" iyz="0.0" izz="0.141666666667"/>
    </inertial>
  </link>
  <joint name="LF_base_clause_joint" type="continuous">
    <origin rpy="0.0 0.0 1.57079637" xyz="0.15 0.2 0"/>
    <parent link="base_link"/>
    <child link="LF_base_clause_link"/>
    <origin rpy="0 0 0" xyz="0 0 0"/>
    <axis xyz="0 0 1"/>
  </joint>
  <link name="LF_base_clause_link">
    <visual>
      <origin rpy="0 0 0" xyz="0 0 0"/>
      <geometry>
        <cylinder length="0.05" radius="0.03"/>
      </geometry>
      &gt;
	  
    </visual>
    <collision>
      <origin rpy="0 0 0" xyz="0 0 0"/>
      <geometry>
        <cylinder length="0.05" radius="0.03"/>
      </geometry>
    </collision>
    <inertial>
      <origin rpy="0 0 0" xyz="0 0 0"/>
      <mass value="0.1"/>
      <inertia ixx="4.33333333333e-05" ixy="0" ixz="0" iyy="4.33333333333e-05" iyz="0" izz="4.5e-05"/>
    </inertial>
  </link>
  <joint name="LF_thigh_joint" type="continuous">
    <origin rpy="0.0 -1.57079637 0.0" xyz="0.0 0.0 0.0"/>
    <parent link="LF_base_clause_link"/>
    <child link="LF_thigh_link"/>
    <origin rpy="0 0 0" xyz="0 0 0"/>
    <axis xyz="0 1 0"/>
  </joint>
  <link name="LF_thigh_link">
    <visual>
      <origin rpy="0 0 0" xyz="0 0 -0.1"/>
      <geometry>
        <cylinder length="0.2" radius="0.03"/>
      </geometry>
      &gt;
	  
    </visual>
    <collision>
      <origin rpy="0 0 0" xyz="0 0 -0.1"/>
      <geometry>
        <cylinder length="0.2" radius="0.03"/>
      </geometry>
    </collision>
    <inertial>
      <origin rpy="0 0 0" xyz="0 0 -0.1"/>
      <mass value="0.6"/>
      <inertia ixx="0.002135" ixy="0" ixz="0" iyy="0.002135" iyz="0" izz="0.00027"/>
    </inertial>
  </link>
  <joint name="LF_tibia_joint" type="continuous">
    <origin rpy="0.0 1.57079637 0.0" xyz="0.0 0.0 -0.2"/>
    <parent link="LF_thigh_link"/>
    <child link="LF_tibia_link"/>
    <origin rpy="0 0 0" xyz="0 0 0"/>
    <axis xyz="0 1 0"/>
  </joint>
  <link name="LF_tibia_link">
    <visual>
      <origin rpy="0 0 0" xyz="0 0 -0.15"/>
      <geometry>
        <cylinder length="0.3" radius="0.03"/>
      </geometry>
      &gt;
	  
    </visual>
    <collision>
      <origin rpy="0 0 0" xyz="0 0 -0.15"/>
      <geometry>
        <cylinder length="0.3" radius="0.03"/>
      </geometry>
    </collision>
    <inertial>
      <origin rpy="0 0 0" xyz="0 0 -0.15"/>
      <mass value="0.7"/>
      <inertia ixx="0.0054075" ixy="0" ixz="0" iyy="0.0054075" iyz="0" izz="0.000315"/>
    </inertial>
  </link>
  <joint name="LF_appendix_joint" type="fixed">
    <origin rpy="0.0 0.0 0.0" xyz="0.0 0.0 -0.3"/>
    <parent link="LF_tibia_link"/>
    <child link="LF_appendix_link"/>
    <origin rpy="0 0 0" xyz="0 0 0"/>
  </joint>
  <link name="LF_appendix_link">
    <visual>
      <origin rpy="0 0 0" xyz="0 0 0"/>
      <geometry>
        <sphere radius="0.03"/>
      </geometry>
      &gt;
	  
    </visual>
    <collision>
      <origin rpy="0 0 0" xyz="0 0 0"/>
      <geometry>
        <sphere radius="0.03"/>
      </geometry>
    </collision>
    <inertial>
      <origin rpy="0 0 0" xyz="0 0 0"/>
      <mass value="0.05"/>
      <inertia ixx="1.8e-05" ixy="0.0" ixz="0.0" iyy="1.8e-05" iyz="0.0" izz="1.8e-05"/>
    </inertial>
  </link>
  <transmission name="LF_base_clause_trans">
    <type>transmission_interface/SimpleTransmission</type>
    <joint name="LF_base_clause_joint">
      <hardwareInterface>hardware_interface/EffortJointInterface</hardwareInterface>
    </joint>
    <actuator name="LF_base_clause_motor">
      <hardwareInterface>hardware_interface/EffortJointInterface</hardwareInterface>
      <mechanicalReduction>30</mechanicalReduction>
    </actuator>
  </transmission>
  <transmission name="LF_thigh_trans">
    <type>transmission_interface/SimpleTransmission</type>
    <joint name="LF_thigh_joint">
      <hardwareInterface>hardware_interface/EffortJointInterface</hardwareInterface>
    </joint>
    <actuator name="LF_thigh_motor">
      <hardwareInterface>hardware_interface/EffortJointInterface</hardwareInterface>
      <mechanicalReduction>30</mechanicalReduction>
    </actuator>
  </transmission>
  <transmission name="LF_tibia_trans">
    <type>transmission_interface/SimpleTransmission</type>
    <joint name="LF_tibia_joint">
      <hardwareInterface>hardware_interface/EffortJointInterface</hardwareInterface>
    </joint>
    <actuator name="LF_tibia_motor">
      <hardwareInterface>hardware_interface/EffortJointInterface</hardwareInterface>
      <mechanicalReduction>30</mechanicalReduction>
    </actuator>
  </transmission>
  <gazebo reference="LF_base_clause_link">
    <selfCollide>false</selfCollide>
    <mu1 value="0.4"/>
    <mu2 value="0.4"/>
    <material>Gazebo/Blue</material>
  </gazebo>
  <gazebo reference="LF_thigh_link">
    <selfCollide>false</selfCollide>
    <mu1 value="0.4"/>
    <mu2 value="0.4"/>
    <material>Gazebo/Yellow</material>
  </gazebo>
  <gazebo reference="LF_tibia_link">
    <selfCollide>false</selfCollide>
    <mu1 value="0.8"/>
    <mu2 value="0.8"/>
    <material>Gazebo/Orange</material>
  </gazebo>
  <gazebo reference="LF_appendix_link">
    <selfCollide>false</selfCollide>
    <mu1 value="10.0"/>
    <mu2 value="10.0"/>
    <material>Gazebo/Red</material>
  </gazebo>
  <joint name="LM_base_clause_joint" type="continuous">
    <origin rpy="0.0 0.0 1.57079637" xyz="0.0 0.2 0"/>
    <parent link="base_link"/>
    <child link="LM_base_clause_link"/>
    <origin rpy="0 0 0" xyz="0 0 0"/>
    <axis xyz="0 0 1"/>
  </joint>
  <link name="LM_base_clause_link">
    <visual>
      <origin rpy="0 0 0" xyz="0 0 0"/>
      <geometry>
        <cylinder length="0.05" radius="0.03"/>
      </geometry>
      &gt;
	  
    </visual>
    <collision>
      <origin rpy="0 0 0" xyz="0 0 0"/>
      <geometry>
        <cylinder length="0.05" radius="0.03"/>
      </geometry>
    </collision>
    <inertial>
      <origin rpy="0 0 0" xyz="0 0 0"/>
      <mass value="0.1"/>
      <inertia ixx="4.33333333333e-05" ixy="0" ixz="0" iyy="4.33333333333e-05" iyz="0" izz="4.5e-05"/>
    </inertial>
  </link>
  <joint name="LM_thigh_joint" type="continuous">
    <origin rpy="0.0 -1.57079637 0.0" xyz="0.0 0.0 0.0"/>
    <parent link="LM_base_clause_link"/>
    <child link="LM_thigh_link"/>
    <origin rpy="0 0 0" xyz="0 0 0"/>
    <axis xyz="0 1 0"/>
  </joint>
  <link name="LM_thigh_link">
    <visual>
      <origin rpy="0 0 0" xyz="0 0 -0.1"/>
      <geometry>
        <cylinder length="0.2" radius="0.03"/>
      </geometry>
      &gt;
	  
    </visual>
    <collision>
      <origin rpy="0 0 0" xyz="0 0 -0.1"/>
      <geometry>
        <cylinder length="0.2" radius="0.03"/>
      </geometry>
    </collision>
    <inertial>
      <origin rpy="0 0 0" xyz="0 0 -0.1"/>
      <mass value="0.6"/>
      <inertia ixx="0.002135" ixy="0" ixz="0" iyy="0.002135" iyz="0" izz="0.00027"/>
    </inertial>
  </link>
  <joint name="LM_tibia_joint" type="continuous">
    <origin rpy="0.0 1.57079637 0.0" xyz="0.0 0.0 -0.2"/>
    <parent link="LM_thigh_link"/>
    <child link="LM_tibia_link"/>
    <origin rpy="0 0 0" xyz="0 0 0"/>
    <axis xyz="0 1 0"/>
  </joint>
  <link name="LM_tibia_link">
    <visual>
      <origin rpy="0 0 0" xyz="0 0 -0.15"/>
      <geometry>
        <cylinder length="0.3" radius="0.03"/>
      </geometry>
      &gt;
	  
    </visual>
    <collision>
      <origin rpy="0 0 0" xyz="0 0 -0.15"/>
      <geometry>
        <cylinder length="0.3" radius="0.03"/>
      </geometry>
    </collision>
    <inertial>
      <origin rpy="0 0 0" xyz="0 0 -0.15"/>
      <mass value="0.7"/>
      <inertia ixx="0.0054075" ixy="0" ixz="0" iyy="0.0054075" iyz="0" izz="0.000315"/>
    </inertial>
  </link>
  <joint name="LM_appendix_joint" type="fixed">
    <origin rpy="0.0 0.0 0.0" xyz="0.0 0.0 -0.3"/>
    <parent link="LM_tibia_link"/>
    <child link="LM_appendix_link"/>
    <origin rpy="0 0 0" xyz="0 0 0"/>
  </joint>
  <link name="LM_appendix_link">
    <visual>
      <origin rpy="0 0 0" xyz="0 0 0"/>
      <geometry>
        <sphere radius="0.03"/>
      </geometry>
      &gt;
	  
    </visual>
    <collision>
      <origin rpy="0 0 0" xyz="0 0 0"/>
      <geometry>
        <sphere radius="0.03"/>
      </geometry>
    </collision>
    <inertial>
      <origin rpy="0 0 0" xyz="0 0 0"/>
      <mass value="0.05"/>
      <inertia ixx="1.8e-05" ixy="0.0" ixz="0.0" iyy="1.8e-05" iyz="0.0" izz="1.8e-05"/>
    </inertial>
  </link>
  <transmission name="LM_base_clause_trans">
    <type>transmission_interface/SimpleTransmission</type>
    <joint name="LM_base_clause_joint">
      <hardwareInterface>hardware_interface/EffortJointInterface</hardwareInterface>
    </joint>
    <actuator name="LM_base_clause_motor">
      <hardwareInterface>hardware_interface/EffortJointInterface</hardwareInterface>
      <mechanicalReduction>30</mechanicalReduction>
    </actuator>
  </transmission>
  <transmission name="LM_thigh_trans">
    <type>transmission_interface/SimpleTransmission</type>
    <joint name="LM_thigh_joint">
      <hardwareInterface>hardware_interface/EffortJointInterface</hardwareInterface>
    </joint>
    <actuator name="LM_thigh_motor">
      <hardwareInterface>hardware_interface/EffortJointInterface</hardwareInterface>
      <mechanicalReduction>30</mechanicalReduction>
    </actuator>
  </transmission>
  <transmission name="LM_tibia_trans">
    <type>transmission_interface/SimpleTransmission</type>
    <joint name="LM_tibia_joint">
      <hardwareInterface>hardware_interface/EffortJointInterface</hardwareInterface>
    </joint>
    <actuator name="LM_tibia_motor">
      <hardwareInterface>hardware_interface/EffortJointInterface</hardwareInterface>
      <mechanicalReduction>30</mechanicalReduction>
    </actuator>
  </transmission>
  <gazebo reference="LM_base_clause_link">
    <selfCollide>false</selfCollide>
    <mu1 value="0.4"/>
    <mu2 value="0.4"/>
    <material>Gazebo/Blue</material>
  </gazebo>
  <gazebo reference="LM_thigh_link">
    <selfCollide>false</selfCollide>
    <mu1 value="0.4"/>
    <mu2 value="0.4"/>
    <material>Gazebo/Yellow</material>
  </gazebo>
  <gazebo reference="LM_tibia_link">
    <selfCollide>false</selfCollide>
    <mu1 value="0.8"/>
    <mu2 value="0.8"/>
    <material>Gazebo/Orange</material>
  </gazebo>
  <gazebo reference="LM_appendix_link">
    <selfCollide>false</selfCollide>
    <mu1 value="10.0"/>
    <mu2 value="10.0"/>
    <material>Gazebo/Red</material>
  </gazebo>
  <joint name="LH_base_clause_joint" type="continuous">
    <origin rpy="0.0 0.0 1.57079637" xyz="-0.15 0.2 0"/>
    <parent link="base_link"/>
    <child link="LH_base_clause_link"/>
    <origin rpy="0 0 0" xyz="0 0 0"/>
    <axis xyz="0 0 1"/>
  </joint>
  <link name="LH_base_clause_link">
    <visual>
      <origin rpy="0 0 0" xyz="0 0 0"/>
      <geometry>
        <cylinder length="0.05" radius="0.03"/>
      </geometry>
      &gt;
	  
    </visual>
    <collision>
      <origin rpy="0 0 0" xyz="0 0 0"/>
      <geometry>
        <cylinder length="0.05" radius="0.03"/>
      </geometry>
    </collision>
    <inertial>
      <origin rpy="0 0 0" xyz="0 0 0"/>
      <mass value="0.1"/>
      <inertia ixx="4.33333333333e-05" ixy="0" ixz="0" iyy="4.33333333333e-05" iyz="0" izz="4.5e-05"/>
    </inertial>
  </link>
  <joint name="LH_thigh_joint" type="continuous">
    <origin rpy="0.0 -1.57079637 0.0" xyz="0.0 0.0 0.0"/>
    <parent link="LH_base_clause_link"/>
    <child link="LH_thigh_link"/>
    <origin rpy="0 0 0" xyz="0 0 0"/>
    <axis xyz="0 1 0"/>
  </joint>
  <link name="LH_thigh_link">
    <visual>
      <origin rpy="0 0 0" xyz="0 0 -0.1"/>
      <geometry>
        <cylinder length="0.2" radius="0.03"/>
      </geometry>
      &gt;
	  
    </visual>
    <collision>
      <origin rpy="0 0 0" xyz="0 0 -0.1"/>
      <geometry>
        <cylinder length="0.2" radius="0.03"/>
      </geometry>
    </collision>
    <inertial>
      <origin rpy="0 0 0" xyz="0 0 -0.1"/>
      <mass value="0.6"/>
      <inertia ixx="0.002135" ixy="0" ixz="0" iyy="0.002135" iyz="0" izz="0.00027"/>
    </inertial>
  </link>
  <joint name="LH_tibia_joint" type="continuous">
    <origin rpy="0.0 1.57079637 0.0" xyz="0.0 0.0 -0.2"/>
    <parent link="LH_thigh_link"/>
    <child link="LH_tibia_link"/>
    <origin rpy="0 0 0" xyz="0 0 0"/>
    <axis xyz="0 1 0"/>
  </joint>
  <link name="LH_tibia_link">
    <visual>
      <origin rpy="0 0 0" xyz="0 0 -0.15"/>
      <geometry>
        <cylinder length="0.3" radius="0.03"/>
      </geometry>
      &gt;
	  
    </visual>
    <collision>
      <origin rpy="0 0 0" xyz="0 0 -0.15"/>
      <geometry>
        <cylinder length="0.3" radius="0.03"/>
      </geometry>
    </collision>
    <inertial>
      <origin rpy="0 0 0" xyz="0 0 -0.15"/>
      <mass value="0.7"/>
      <inertia ixx="0.0054075" ixy="0" ixz="0" iyy="0.0054075" iyz="0" izz="0.000315"/>
    </inertial>
  </link>
  <joint name="LH_appendix_joint" type="fixed">
    <origin rpy="0.0 0.0 0.0" xyz="0.0 0.0 -0.3"/>
    <parent link="LH_tibia_link"/>
    <child link="LH_appendix_link"/>
    <origin rpy="0 0 0" xyz="0 0 0"/>
  </joint>
  <link name="LH_appendix_link">
    <visual>
      <origin rpy="0 0 0" xyz="0 0 0"/>
      <geometry>
        <sphere radius="0.03"/>
      </geometry>
      &gt;
	  
    </visual>
    <collision>
      <origin rpy="0 0 0" xyz="0 0 0"/>
      <geometry>
        <sphere radius="0.03"/>
      </geometry>
    </collision>
    <inertial>
      <origin rpy="0 0 0" xyz="0 0 0"/>
      <mass value="0.05"/>
      <inertia ixx="1.8e-05" ixy="0.0" ixz="0.0" iyy="1.8e-05" iyz="0.0" izz="1.8e-05"/>
    </inertial>
  </link>
  <transmission name="LH_base_clause_trans">
    <type>transmission_interface/SimpleTransmission</type>
    <joint name="LH_base_clause_joint">
      <hardwareInterface>hardware_interface/EffortJointInterface</hardwareInterface>
    </joint>
    <actuator name="LH_base_clause_motor">
      <hardwareInterface>hardware_interface/EffortJointInterface</hardwareInterface>
      <mechanicalReduction>30</mechanicalReduction>
    </actuator>
  </transmission>
  <transmission name="LH_thigh_trans">
    <type>transmission_interface/SimpleTransmission</type>
    <joint name="LH_thigh_joint">
      <hardwareInterface>hardware_interface/EffortJointInterface</hardwareInterface>
    </joint>
    <actuator name="LH_thigh_motor">
      <hardwareInterface>hardware_interface/EffortJointInterface</hardwareInterface>
      <mechanicalReduction>30</mechanicalReduction>
    </actuator>
  </transmission>
  <transmission name="LH_tibia_trans">
    <type>transmission_interface/SimpleTransmission</type>
    <joint name="LH_tibia_joint">
      <hardwareInterface>hardware_interface/EffortJointInterface</hardwareInterface>
    </joint>
    <actuator name="LH_tibia_motor">
      <hardwareInterface>hardware_interface/EffortJointInterface</hardwareInterface>
      <mechanicalReduction>30</mechanicalReduction>
    </actuator>
  </transmission>
  <gazebo reference="LH_base_clause_link">
    <selfCollide>false</selfCollide>
    <mu1 value="0.4"/>
    <mu2 value="0.4"/>
    <material>Gazebo/Blue</material>
  </gazebo>
  <gazebo reference="LH_thigh_link">
    <selfCollide>false</selfCollide>
    <mu1 value="0.4"/>
    <mu2 value="0.4"/>
    <material>Gazebo/Yellow</material>
  </gazebo>
  <gazebo reference="LH_tibia_link">
    <selfCollide>false</selfCollide>
    <mu1 value="0.8"/>
    <mu2 value="0.8"/>
    <material>Gazebo/Orange</material>
  </gazebo>
  <gazebo reference="LH_appendix_link">
    <selfCollide>false</selfCollide>
    <mu1 value="10.0"/>
    <mu2 value="10.0"/>
    <material>Gazebo/Red</material>
  </gazebo>
  <joint name="RF_base_clause_joint" type="continuous">
    <origin rpy="0.0 0.0 -1.57079637" xyz="0.15 -0.2 0"/>
    <parent link="base_link"/>
    <child link="RF_base_clause_link"/>
    <origin rpy="0 0 0" xyz="0 0 0"/>
    <axis xyz="0 0 1"/>
  </joint>
  <link name="RF_base_clause_link">
    <visual>
      <origin rpy="0 0 0" xyz="0 0 0"/>
      <geometry>
        <cylinder length="0.05" radius="0.03"/>
      </geometry>
      &gt;
	  
    </visual>
    <collision>
      <origin rpy="0 0 0" xyz="0 0 0"/>
      <geometry>
        <cylinder length="0.05" radius="0.03"/>
      </geometry>
    </collision>
    <inertial>
      <origin rpy="0 0 0" xyz="0 0 0"/>
      <mass value="0.1"/>
      <inertia ixx="4.33333333333e-05" ixy="0" ixz="0" iyy="4.33333333333e-05" iyz="0" izz="4.5e-05"/>
    </inertial>
  </link>
  <joint name="RF_thigh_joint" type="continuous">
    <origin rpy="0.0 -1.57079637 0.0" xyz="0.0 0.0 0.0"/>
    <parent link="RF_base_clause_link"/>
    <child link="RF_thigh_link"/>
    <origin rpy="0 0 0" xyz="0 0 0"/>
    <axis xyz="0 1 0"/>
  </joint>
  <link name="RF_thigh_link">
    <visual>
      <origin rpy="0 0 0" xyz="0 0 -0.1"/>
      <geometry>
        <cylinder length="0.2" radius="0.03"/>
      </geometry>
      &gt;
	  
    </visual>
    <collision>
      <origin rpy="0 0 0" xyz="0 0 -0.1"/>
      <geometry>
        <cylinder length="0.2" radius="0.03"/>
      </geometry>
    </collision>
    <inertial>
      <origin rpy="0 0 0" xyz="0 0 -0.1"/>
      <mass value="0.6"/>
      <inertia ixx="0.002135" ixy="0" ixz="0" iyy="0.002135" iyz="0" izz="0.00027"/>
    </inertial>
  </link>
  <joint name="RF_tibia_joint" type="continuous">
    <origin rpy="0.0 1.57079637 0.0" xyz="0.0 0.0 -0.2"/>
    <parent link="RF_thigh_link"/>
    <child link="RF_tibia_link"/>
    <origin rpy="0 0 0" xyz="0 0 0"/>
    <axis xyz="0 1 0"/>
  </joint>
  <link name="RF_tibia_link">
    <visual>
      <origin rpy="0 0 0" xyz="0 0 -0.15"/>
      <geometry>
        <cylinder length="0.3" radius="0.03"/>
      </geometry>
      &gt;
	  
    </visual>
    <collision>
      <origin rpy="0 0 0" xyz="0 0 -0.15"/>
      <geometry>
        <cylinder length="0.3" radius="0.03"/>
      </geometry>
    </collision>
    <inertial>
      <origin rpy="0 0 0" xyz="0 0 -0.15"/>
      <mass value="0.7"/>
      <inertia ixx="0.0054075" ixy="0" ixz="0" iyy="0.0054075" iyz="0" izz="0.000315"/>
    </inertial>
  </link>
  <joint name="RF_appendix_joint" type="fixed">
    <origin rpy="0.0 0.0 0.0" xyz="0.0 0.0 -0.3"/>
    <parent link="RF_tibia_link"/>
    <child link="RF_appendix_link"/>
    <origin rpy="0 0 0" xyz="0 0 0"/>
  </joint>
  <link name="RF_appendix_link">
    <visual>
      <origin rpy="0 0 0" xyz="0 0 0"/>
      <geometry>
        <sphere radius="0.03"/>
      </geometry>
      &gt;
	  
    </visual>
    <collision>
      <origin rpy="0 0 0" xyz="0 0 0"/>
      <geometry>
        <sphere radius="0.03"/>
      </geometry>
    </collision>
    <inertial>
      <origin rpy="0 0 0" xyz="0 0 0"/>
      <mass value="0.05"/>
      <inertia ixx="1.8e-05" ixy="0.0" ixz="0.0" iyy="1.8e-05" iyz="0.0" izz="1.8e-05"/>
    </inertial>
  </link>
  <transmission name="RF_base_clause_trans">
    <type>transmission_interface/SimpleTransmission</type>
    <joint name="RF_base_clause_joint">
      <hardwareInterface>hardware_interface/EffortJointInterface</hardwareInterface>
    </joint>
    <actuator name="RF_base_clause_motor">
      <hardwareInterface>hardware_interface/EffortJointInterface</hardwareInterface>
      <mechanicalReduction>30</mechanicalReduction>
    </actuator>
  </transmission>
  <transmission name="RF_thigh_trans">
    <type>transmission_interface/SimpleTransmission</type>
    <joint name="RF_thigh_joint">
      <hardwareInterface>hardware_interface/EffortJointInterface</hardwareInterface>
    </joint>
    <actuator name="RF_thigh_motor">
      <hardwareInterface>hardware_interface/EffortJointInterface</hardwareInterface>
      <mechanicalReduction>30</mechanicalReduction>
    </actuator>
  </transmission>
  <transmission name="RF_tibia_trans">
    <type>transmission_interface/SimpleTransmission</type>
    <joint name="RF_tibia_joint">
      <hardwareInterface>hardware_interface/EffortJointInterface</hardwareInterface>
    </joint>
    <actuator name="RF_tibia_motor">
      <hardwareInterface>hardware_interface/EffortJointInterface</hardwareInterface>
      <mechanicalReduction>30</mechanicalReduction>
    </actuator>
  </transmission>
  <gazebo reference="RF_base_clause_link">
    <selfCollide>false</selfCollide>
    <mu1 value="0.4"/>
    <mu2 value="0.4"/>
    <material>Gazebo/Blue</material>
  </gazebo>
  <gazebo reference="RF_thigh_link">
    <selfCollide>false</selfCollide>
    <mu1 value="0.4"/>
    <mu2 value="0.4"/>
    <material>Gazebo/Yellow</material>
  </gazebo>
  <gazebo reference="RF_tibia_link">
    <selfCollide>false</selfCollide>
    <mu1 value="0.8"/>
    <mu2 value="0.8"/>
    <material>Gazebo/Orange</material>
  </gazebo>
  <gazebo reference="RF_appendix_link">
    <selfCollide>false</selfCollide>
    <mu1 value="10.0"/>
    <mu2 value="10.0"/>
    <material>Gazebo/Red</material>
  </gazebo>
  <joint name="RM_base_clause_joint" type="continuous">
    <origin rpy="0.0 0.0 -1.57079637" xyz="0.0 -0.2 0"/>
    <parent link="base_link"/>
    <child link="RM_base_clause_link"/>
    <origin rpy="0 0 0" xyz="0 0 0"/>
    <axis xyz="0 0 1"/>
  </joint>
  <link name="RM_base_clause_link">
    <visual>
      <origin rpy="0 0 0" xyz="0 0 0"/>
      <geometry>
        <cylinder length="0.05" radius="0.03"/>
      </geometry>
      &gt;
	  
    </visual>
    <collision>
      <origin rpy="0 0 0" xyz="0 0 0"/>
      <geometry>
        <cylinder length="0.05" radius="0.03"/>
      </geometry>
    </collision>
    <inertial>
      <origin rpy="0 0 0" xyz="0 0 0"/>
      <mass value="0.1"/>
      <inertia ixx="4.33333333333e-05" ixy="0" ixz="0" iyy="4.33333333333e-05" iyz="0" izz="4.5e-05"/>
    </inertial>
  </link>
  <joint name="RM_thigh_joint" type="continuous">
    <origin rpy="0.0 -1.57079637 0.0" xyz="0.0 0.0 0.0"/>
    <parent link="RM_base_clause_link"/>
    <child link="RM_thigh_link"/>
    <origin rpy="0 0 0" xyz="0 0 0"/>
    <axis xyz="0 1 0"/>
  </joint>
  <link name="RM_thigh_link">
    <visual>
      <origin rpy="0 0 0" xyz="0 0 -0.1"/>
      <geometry>
        <cylinder length="0.2" radius="0.03"/>
      </geometry>
      &gt;
	  
    </visual>
    <collision>
      <origin rpy="0 0 0" xyz="0 0 -0.1"/>
      <geometry>
        <cylinder length="0.2" radius="0.03"/>
      </geometry>
    </collision>
    <inertial>
      <origin rpy="0 0 0" xyz="0 0 -0.1"/>
      <mass value="0.6"/>
      <inertia ixx="0.002135" ixy="0" ixz="0" iyy="0.002135" iyz="0" izz="0.00027"/>
    </inertial>
  </link>
  <joint name="RM_tibia_joint" type="continuous">
    <origin rpy="0.0 1.57079637 0.0" xyz="0.0 0.0 -0.2"/>
    <parent link="RM_thigh_link"/>
    <child link="RM_tibia_link"/>
    <origin rpy="0 0 0" xyz="0 0 0"/>
    <axis xyz="0 1 0"/>
  </joint>
  <link name="RM_tibia_link">
    <visual>
      <origin rpy="0 0 0" xyz="0 0 -0.15"/>
      <geometry>
        <cylinder length="0.3" radius="0.03"/>
      </geometry>
      &gt;
	  
    </visual>
    <collision>
      <origin rpy="0 0 0" xyz="0 0 -0.15"/>
      <geometry>
        <cylinder length="0.3" radius="0.03"/>
      </geometry>
    </collision>
    <inertial>
      <origin rpy="0 0 0" xyz="0 0 -0.15"/>
      <mass value="0.7"/>
      <inertia ixx="0.0054075" ixy="0" ixz="0" iyy="0.0054075" iyz="0" izz="0.000315"/>
    </inertial>
  </link>
  <joint name="RM_appendix_joint" type="fixed">
    <origin rpy="0.0 0.0 0.0" xyz="0.0 0.0 -0.3"/>
    <parent link="RM_tibia_link"/>
    <child link="RM_appendix_link"/>
    <origin rpy="0 0 0" xyz="0 0 0"/>
  </joint>
  <link name="RM_appendix_link">
    <visual>
      <origin rpy="0 0 0" xyz="0 0 0"/>
      <geometry>
        <sphere radius="0.03"/>
      </geometry>
      &gt;
	  
    </visual>
    <collision>
      <origin rpy="0 0 0" xyz="0 0 0"/>
      <geometry>
        <sphere radius="0.03"/>
      </geometry>
    </collision>
    <inertial>
      <origin rpy="0 0 0" xyz="0 0 0"/>
      <mass value="0.05"/>
      <inertia ixx="1.8e-05" ixy="0.0" ixz="0.0" iyy="1.8e-05" iyz="0.0" izz="1.8e-05"/>
    </inertial>
  </link>
  <transmission name="RM_base_clause_trans">
    <type>transmission_interface/SimpleTransmission</type>
    <joint name="RM_base_clause_joint">
      <hardwareInterface>hardware_interface/EffortJointInterface</hardwareInterface>
    </joint>
    <actuator name="RM_base_clause_motor">
      <hardwareInterface>hardware_interface/EffortJointInterface</hardwareInterface>
      <mechanicalReduction>30</mechanicalReduction>
    </actuator>
  </transmission>
  <transmission name="RM_thigh_trans">
    <type>transmission_interface/SimpleTransmission</type>
    <joint name="RM_thigh_joint">
      <hardwareInterface>hardware_interface/EffortJointInterface</hardwareInterface>
    </joint>
    <actuator name="RM_thigh_motor">
      <hardwareInterface>hardware_interface/EffortJointInterface</hardwareInterface>
      <mechanicalReduction>30</mechanicalReduction>
    </actuator>
  </transmission>
  <transmission name="RM_tibia_trans">
    <type>transmission_interface/SimpleTransmission</type>
    <joint name="RM_tibia_joint">
      <hardwareInterface>hardware_interface/EffortJointInterface</hardwareInterface>
    </joint>
    <actuator name="RM_tibia_motor">
      <hardwareInterface>hardware_interface/EffortJointInterface</hardwareInterface>
      <mechanicalReduction>30</mechanicalReduction>
    </actuator>
  </transmission>
  <gazebo reference="RM_base_clause_link">
    <selfCollide>false</selfCollide>
    <mu1 value="0.4"/>
    <mu2 value="0.4"/>
    <material>Gazebo/Blue</material>
  </gazebo>
  <gazebo reference="RM_thigh_link">
    <selfCollide>false</selfCollide>
    <mu1 value="0.4"/>
    <mu2 value="0.4"/>
    <material>Gazebo/Yellow</material>
  </gazebo>
  <gazebo reference="RM_tibia_link">
    <selfCollide>false</selfCollide>
    <mu1 value="0.8"/>
    <mu2 value="0.8"/>
    <material>Gazebo/Orange</material>
  </gazebo>
  <gazebo reference="RM_appendix_link">
    <selfCollide>false</selfCollide>
    <mu1 value="10.0"/>
    <mu2 value="10.0"/>
    <material>Gazebo/Red</material>
  </gazebo>
  <joint name="RH_base_clause_joint" type="continuous">
    <origin rpy="0.0 0.0 -1.57079637" xyz="-0.15 -0.2 0"/>
    <parent link="base_link"/>
    <child link="RH_base_clause_link"/>
    <origin rpy="0 0 0" xyz="0 0 0"/>
    <axis xyz="0 0 1"/>
  </joint>
  <link name="RH_base_clause_link">
    <visual>
      <origin rpy="0 0 0" xyz="0 0 0"/>
      <geometry>
        <cylinder length="0.05" radius="0.03"/>
      </geometry>
      &gt;
	  
    </visual>
    <collision>
      <origin rpy="0 0 0" xyz="0 0 0"/>
      <geometry>
        <cylinder length="0.05" radius="0.03"/>
      </geometry>
    </collision>
    <inertial>
      <origin rpy="0 0 0" xyz="0 0 0"/>
      <mass value="0.1"/>
      <inertia ixx="4.33333333333e-05" ixy="0" ixz="0" iyy="4.33333333333e-05" iyz="0" izz="4.5e-05"/>
    </inertial>
  </link>
  <joint name="RH_thigh_joint" type="continuous">
    <origin rpy="0.0 -1.57079637 0.0" xyz="0.0 0.0 0.0"/>
    <parent link="RH_base_clause_link"/>
    <child link="RH_thigh_link"/>
    <origin rpy="0 0 0" xyz="0 0 0"/>
    <axis xyz="0 1 0"/>
  </joint>
  <link name="RH_thigh_link">
    <visual>
      <origin rpy="0 0 0" xyz="0 0 -0.1"/>
      <geometry>
        <cylinder length="0.2" radius="0.03"/>
      </geometry>
      &gt;
	  
    </visual>
    <collision>
      <origin rpy="0 0 0" xyz="0 0 -0.1"/>
      <geometry>
        <cylinder length="0.2" radius="0.03"/>
      </geometry>
    </collision>
    <inertial>
      <origin rpy="0 0 0" xyz="0 0 -0.1"/>
      <mass value="0.6"/>
      <inertia ixx="0.002135" ixy="0" ixz="0" iyy="0.002135" iyz="0" izz="0.00027"/>
    </inertial>
  </link>
  <joint name="RH_tibia_joint" type="continuous">
    <origin rpy="0.0 1.57079637 0.0" xyz="0.0 0.0 -0.2"/>
    <parent link="RH_thigh_link"/>
    <child link="RH_tibia_link"/>
    <origin rpy="0 0 0" xyz="0 0 0"/>
    <axis xyz="0 1 0"/>
  </joint>
  <link name="RH_tibia_link">
    <visual>
      <origin rpy="0 0 0" xyz="0 0 -0.15"/>
      <geometry>
        <cylinder length="0.3" radius="0.03"/>
      </geometry>
      &gt;
	  
    </visual>
    <collision>
      <origin rpy="0 0 0" xyz="0 0 -0.15"/>
      <geometry>
        <cylinder length="0.3" radius="0.03"/>
      </geometry>
    </collision>
    <inertial>
      <origin rpy="0 0 0" xyz="0 0 -0.15"/>
      <mass value="0.7"/>
      <inertia ixx="0.0054075" ixy="0" ixz="0" iyy="0.0054075" iyz="0" izz="0.000315"/>
    </inertial>
  </link>
  <joint name="RH_appendix_joint" type="fixed">
    <origin rpy="0.0 0.0 0.0" xyz="0.0 0.0 -0.3"/>
    <parent link="RH_tibia_link"/>
    <child link="RH_appendix_link"/>
    <origin rpy="0 0 0" xyz="0 0 0"/>
  </joint>
  <link name="RH_appendix_link">
    <visual>
      <origin rpy="0 0 0" xyz="0 0 0"/>
      <geometry>
        <sphere radius="0.03"/>
      </geometry>
      &gt;
	  
    </visual>
    <collision>
      <origin rpy="0 0 0" xyz="0 0 0"/>
      <geometry>
        <sphere radius="0.03"/>
      </geometry>
    </collision>
    <inertial>
      <origin rpy="0 0 0" xyz="0 0 0"/>
      <mass value="0.05"/>
      <inertia ixx="1.8e-05" ixy="0.0" ixz="0.0" iyy="1.8e-05" iyz="0.0" izz="1.8e-05"/>
    </inertial>
  </link>
  <transmission name="RH_base_clause_trans">
    <type>transmission_interface/SimpleTransmission</type>
    <joint name="RH_base_clause_joint">
      <hardwareInterface>hardware_interface/EffortJointInterface</hardwareInterface>
    </joint>
    <actuator name="RH_base_clause_motor">
      <hardwareInterface>hardware_interface/EffortJointInterface</hardwareInterface>
      <mechanicalReduction>30</mechanicalReduction>
    </actuator>
  </transmission>
  <transmission name="RH_thigh_trans">
    <type>transmission_interface/SimpleTransmission</type>
    <joint name="RH_thigh_joint">
      <hardwareInterface>hardware_interface/EffortJointInterface</hardwareInterface>
    </joint>
    <actuator name="RH_thigh_motor">
      <hardwareInterface>hardware_interface/EffortJointInterface</hardwareInterface>
      <mechanicalReduction>30</mechanicalReduction>
    </actuator>
  </transmission>
  <transmission name="RH_tibia_trans">
    <type>transmission_interface/SimpleTransmission</type>
    <joint name="RH_tibia_joint">
      <hardwareInterface>hardware_interface/EffortJointInterface</hardwareInterface>
    </joint>
    <actuator name="RH_tibia_motor">
      <hardwareInterface>hardware_interface/EffortJointInterface</hardwareInterface>
      <mechanicalReduction>30</mechanicalReduction>
    </actuator>
  </transmission>
  <gazebo reference="RH_base_clause_link">
    <selfCollide>false</selfCollide>
    <mu1 value="0.4"/>
    <mu2 value="0.4"/>
    <material>Gazebo/Blue</material>
  </gazebo>
  <gazebo reference="RH_thigh_link">
    <selfCollide>false</selfCollide>
    <mu1 value="0.4"/>
    <mu2 value="0.4"/>
    <material>Gazebo/Yellow</material>
  </gazebo>
  <gazebo reference="RH_tibia_link">
    <selfCollide>false</selfCollide>
    <mu1 value="0.8"/>
    <mu2 value="0.8"/>
    <material>Gazebo/Orange</material>
  </gazebo>
  <gazebo reference="RH_appendix_link">
    <selfCollide>false</selfCollide>
    <mu1 value="10.0"/>
    <mu2 value="10.0"/>
    <material>Gazebo/Red</material>
  </gazebo>
  <!-- =============== Gazebo =============== -->
  <gazebo>
    <plugin filename="libgazebo_ros_control.so" name="gazebo_ros_control">
      <robotNamespace>/multi_legged_robot</robotNamespace>
      <robotSimType>gazebo_ros_control/DefaultRobotHWSim</robotSimType>
    </plugin>
  </gazebo>
  <gazebo reference="base_link">
    <selfCollide>false</selfCollide>
    <mu1 value="0.3"/>
    <mu2 value="0.3"/>
    <material>Gazebo/Black</material>
  </gazebo>
  <!-- <xacro:base_clause_gazebo_control rate="25"/> -->
</robot>

